{
 "cells": [
  {
   "cell_type": "markdown",
   "metadata": {},
   "source": [
    "# Forger"
   ]
  },
  {
   "cell_type": "markdown",
   "metadata": {},
   "source": [
    "This is a notebook about General Adversarial Networks. Data from Kaggle : https://www.kaggle.com/ikarus777/best-artworks-of-all-time. "
   ]
  },
  {
   "cell_type": "code",
   "execution_count": 2,
   "metadata": {},
   "outputs": [
    {
     "name": "stderr",
     "output_type": "stream",
     "text": [
      "ERROR:root:Internal Python error in the inspect module.\n",
      "Below is the traceback from this internal error.\n",
      "\n",
      "ERROR:root:Internal Python error in the inspect module.\n",
      "Below is the traceback from this internal error.\n",
      "\n"
     ]
    },
    {
     "name": "stdout",
     "output_type": "stream",
     "text": [
      "Traceback (most recent call last):\n",
      "  File \"c:\\users\\mady\\appdata\\local\\programs\\python\\python37\\lib\\site-packages\\keras\\__init__.py\", line 3, in <module>\n",
      "    from tensorflow.keras.layers.experimental.preprocessing import RandomRotation\n",
      "  File \"c:\\users\\mady\\appdata\\local\\programs\\python\\python37\\lib\\site-packages\\tensorflow\\__init__.py\", line 50, in __getattr__\n",
      "    from ._api.v2 import data\n",
      "  File \"c:\\users\\mady\\appdata\\local\\programs\\python\\python37\\lib\\site-packages\\tensorflow\\__init__.py\", line 44, in _load\n",
      "    from ._api.v2 import audio\n",
      "  File \"c:\\users\\mady\\appdata\\local\\programs\\python\\python37\\lib\\importlib\\__init__.py\", line 127, in import_module\n",
      "    return _bootstrap._gcd_import(name[level:], package, level)\n",
      "ModuleNotFoundError: No module named 'tensorflow_core'\n",
      "\n",
      "During handling of the above exception, another exception occurred:\n",
      "\n",
      "Traceback (most recent call last):\n",
      "  File \"c:\\users\\mady\\appdata\\local\\programs\\python\\python37\\lib\\site-packages\\IPython\\core\\interactiveshell.py\", line 3326, in run_code\n",
      "    exec(code_obj, self.user_global_ns, self.user_ns)\n",
      "  File \"<ipython-input-2-61646e097329>\", line 1, in <module>\n",
      "    import keras\n",
      "  File \"c:\\users\\mady\\appdata\\local\\programs\\python\\python37\\lib\\site-packages\\keras\\__init__.py\", line 6, in <module>\n",
      "    'Keras requires TensorFlow 2.2 or higher. '\n",
      "ImportError: Keras requires TensorFlow 2.2 or higher. Install TensorFlow via `pip install tensorflow`\n",
      "\n",
      "During handling of the above exception, another exception occurred:\n",
      "\n",
      "Traceback (most recent call last):\n",
      "  File \"c:\\users\\mady\\appdata\\local\\programs\\python\\python37\\lib\\site-packages\\IPython\\core\\interactiveshell.py\", line 2040, in showtraceback\n",
      "    stb = value._render_traceback_()\n",
      "AttributeError: 'ImportError' object has no attribute '_render_traceback_'\n",
      "\n",
      "During handling of the above exception, another exception occurred:\n",
      "\n",
      "Traceback (most recent call last):\n",
      "  File \"c:\\users\\mady\\appdata\\local\\programs\\python\\python37\\lib\\site-packages\\IPython\\core\\ultratb.py\", line 1101, in get_records\n",
      "    return _fixed_getinnerframes(etb, number_of_lines_of_context, tb_offset)\n",
      "  File \"c:\\users\\mady\\appdata\\local\\programs\\python\\python37\\lib\\site-packages\\IPython\\core\\ultratb.py\", line 319, in wrapped\n",
      "    return f(*args, **kwargs)\n",
      "  File \"c:\\users\\mady\\appdata\\local\\programs\\python\\python37\\lib\\site-packages\\IPython\\core\\ultratb.py\", line 353, in _fixed_getinnerframes\n",
      "    records = fix_frame_records_filenames(inspect.getinnerframes(etb, context))\n",
      "  File \"c:\\users\\mady\\appdata\\local\\programs\\python\\python37\\lib\\inspect.py\", line 1502, in getinnerframes\n",
      "    frameinfo = (tb.tb_frame,) + getframeinfo(tb, context)\n",
      "  File \"c:\\users\\mady\\appdata\\local\\programs\\python\\python37\\lib\\inspect.py\", line 1460, in getframeinfo\n",
      "    filename = getsourcefile(frame) or getfile(frame)\n",
      "  File \"c:\\users\\mady\\appdata\\local\\programs\\python\\python37\\lib\\inspect.py\", line 696, in getsourcefile\n",
      "    if getattr(getmodule(object, filename), '__loader__', None) is not None:\n",
      "  File \"c:\\users\\mady\\appdata\\local\\programs\\python\\python37\\lib\\inspect.py\", line 733, in getmodule\n",
      "    if ismodule(module) and hasattr(module, '__file__'):\n",
      "  File \"c:\\users\\mady\\appdata\\local\\programs\\python\\python37\\lib\\site-packages\\tensorflow\\__init__.py\", line 50, in __getattr__\n",
      "    from ._api.v2 import data\n",
      "  File \"c:\\users\\mady\\appdata\\local\\programs\\python\\python37\\lib\\site-packages\\tensorflow\\__init__.py\", line 44, in _load\n",
      "    from ._api.v2 import audio\n",
      "  File \"c:\\users\\mady\\appdata\\local\\programs\\python\\python37\\lib\\importlib\\__init__.py\", line 127, in import_module\n",
      "    return _bootstrap._gcd_import(name[level:], package, level)\n",
      "  File \"<frozen importlib._bootstrap>\", line 1006, in _gcd_import\n",
      "  File \"<frozen importlib._bootstrap>\", line 983, in _find_and_load\n",
      "  File \"<frozen importlib._bootstrap>\", line 953, in _find_and_load_unlocked\n",
      "  File \"<frozen importlib._bootstrap>\", line 219, in _call_with_frames_removed\n",
      "  File \"<frozen importlib._bootstrap>\", line 1006, in _gcd_import\n",
      "  File \"<frozen importlib._bootstrap>\", line 983, in _find_and_load\n",
      "  File \"<frozen importlib._bootstrap>\", line 965, in _find_and_load_unlocked\n",
      "ModuleNotFoundError: No module named 'tensorflow_core'\n",
      "Traceback (most recent call last):\n",
      "  File \"c:\\users\\mady\\appdata\\local\\programs\\python\\python37\\lib\\site-packages\\keras\\__init__.py\", line 3, in <module>\n",
      "    from tensorflow.keras.layers.experimental.preprocessing import RandomRotation\n",
      "  File \"c:\\users\\mady\\appdata\\local\\programs\\python\\python37\\lib\\site-packages\\tensorflow\\__init__.py\", line 50, in __getattr__\n",
      "    from ._api.v2 import data\n",
      "  File \"c:\\users\\mady\\appdata\\local\\programs\\python\\python37\\lib\\site-packages\\tensorflow\\__init__.py\", line 44, in _load\n",
      "    from ._api.v2 import audio\n",
      "  File \"c:\\users\\mady\\appdata\\local\\programs\\python\\python37\\lib\\importlib\\__init__.py\", line 127, in import_module\n",
      "    return _bootstrap._gcd_import(name[level:], package, level)\n",
      "ModuleNotFoundError: No module named 'tensorflow_core'\n",
      "\n",
      "During handling of the above exception, another exception occurred:\n",
      "\n",
      "Traceback (most recent call last):\n",
      "  File \"c:\\users\\mady\\appdata\\local\\programs\\python\\python37\\lib\\site-packages\\IPython\\core\\interactiveshell.py\", line 3326, in run_code\n",
      "    exec(code_obj, self.user_global_ns, self.user_ns)\n",
      "  File \"<ipython-input-2-61646e097329>\", line 1, in <module>\n",
      "    import keras\n",
      "  File \"c:\\users\\mady\\appdata\\local\\programs\\python\\python37\\lib\\site-packages\\keras\\__init__.py\", line 6, in <module>\n",
      "    'Keras requires TensorFlow 2.2 or higher. '\n",
      "ImportError: Keras requires TensorFlow 2.2 or higher. Install TensorFlow via `pip install tensorflow`\n",
      "\n",
      "During handling of the above exception, another exception occurred:\n",
      "\n",
      "Traceback (most recent call last):\n",
      "  File \"c:\\users\\mady\\appdata\\local\\programs\\python\\python37\\lib\\site-packages\\IPython\\core\\interactiveshell.py\", line 2040, in showtraceback\n",
      "    stb = value._render_traceback_()\n",
      "AttributeError: 'ImportError' object has no attribute '_render_traceback_'\n",
      "\n",
      "During handling of the above exception, another exception occurred:\n",
      "\n",
      "Traceback (most recent call last):\n",
      "  File \"c:\\users\\mady\\appdata\\local\\programs\\python\\python37\\lib\\site-packages\\IPython\\core\\interactiveshell.py\", line 3249, in run_ast_nodes\n",
      "    if (await self.run_code(code, result,  async_=asy)):\n",
      "  File \"c:\\users\\mady\\appdata\\local\\programs\\python\\python37\\lib\\site-packages\\IPython\\core\\interactiveshell.py\", line 3343, in run_code\n",
      "    self.showtraceback(running_compiled_code=True)\n",
      "  File \"c:\\users\\mady\\appdata\\local\\programs\\python\\python37\\lib\\site-packages\\IPython\\core\\interactiveshell.py\", line 2043, in showtraceback\n",
      "    value, tb, tb_offset=tb_offset)\n",
      "  File \"c:\\users\\mady\\appdata\\local\\programs\\python\\python37\\lib\\site-packages\\IPython\\core\\ultratb.py\", line 1385, in structured_traceback\n",
      "    self, etype, value, tb, tb_offset, number_of_lines_of_context)\n",
      "  File \"c:\\users\\mady\\appdata\\local\\programs\\python\\python37\\lib\\site-packages\\IPython\\core\\ultratb.py\", line 1288, in structured_traceback\n",
      "    self, etype, value, tb, tb_offset, number_of_lines_of_context\n",
      "  File \"c:\\users\\mady\\appdata\\local\\programs\\python\\python37\\lib\\site-packages\\IPython\\core\\ultratb.py\", line 1150, in structured_traceback\n",
      "    formatted_exceptions += self.prepare_chained_exception_message(evalue.__cause__)\n",
      "TypeError: can only concatenate str (not \"list\") to str\n",
      "\n",
      "During handling of the above exception, another exception occurred:\n",
      "\n",
      "Traceback (most recent call last):\n",
      "  File \"c:\\users\\mady\\appdata\\local\\programs\\python\\python37\\lib\\site-packages\\IPython\\core\\interactiveshell.py\", line 2040, in showtraceback\n",
      "    stb = value._render_traceback_()\n",
      "AttributeError: 'TypeError' object has no attribute '_render_traceback_'\n",
      "\n",
      "During handling of the above exception, another exception occurred:\n",
      "\n",
      "Traceback (most recent call last):\n",
      "  File \"c:\\users\\mady\\appdata\\local\\programs\\python\\python37\\lib\\site-packages\\IPython\\core\\ultratb.py\", line 1101, in get_records\n",
      "    return _fixed_getinnerframes(etb, number_of_lines_of_context, tb_offset)\n",
      "  File \"c:\\users\\mady\\appdata\\local\\programs\\python\\python37\\lib\\site-packages\\IPython\\core\\ultratb.py\", line 319, in wrapped\n",
      "    return f(*args, **kwargs)\n",
      "  File \"c:\\users\\mady\\appdata\\local\\programs\\python\\python37\\lib\\site-packages\\IPython\\core\\ultratb.py\", line 353, in _fixed_getinnerframes\n",
      "    records = fix_frame_records_filenames(inspect.getinnerframes(etb, context))\n",
      "  File \"c:\\users\\mady\\appdata\\local\\programs\\python\\python37\\lib\\inspect.py\", line 1502, in getinnerframes\n",
      "    frameinfo = (tb.tb_frame,) + getframeinfo(tb, context)\n",
      "  File \"c:\\users\\mady\\appdata\\local\\programs\\python\\python37\\lib\\inspect.py\", line 1460, in getframeinfo\n",
      "    filename = getsourcefile(frame) or getfile(frame)\n",
      "  File \"c:\\users\\mady\\appdata\\local\\programs\\python\\python37\\lib\\inspect.py\", line 696, in getsourcefile\n",
      "    if getattr(getmodule(object, filename), '__loader__', None) is not None:\n",
      "  File \"c:\\users\\mady\\appdata\\local\\programs\\python\\python37\\lib\\inspect.py\", line 733, in getmodule\n",
      "    if ismodule(module) and hasattr(module, '__file__'):\n",
      "  File \"c:\\users\\mady\\appdata\\local\\programs\\python\\python37\\lib\\site-packages\\tensorflow\\__init__.py\", line 50, in __getattr__\n",
      "    from ._api.v2 import data\n",
      "  File \"c:\\users\\mady\\appdata\\local\\programs\\python\\python37\\lib\\site-packages\\tensorflow\\__init__.py\", line 44, in _load\n",
      "    from ._api.v2 import audio\n",
      "  File \"c:\\users\\mady\\appdata\\local\\programs\\python\\python37\\lib\\importlib\\__init__.py\", line 127, in import_module\n",
      "    return _bootstrap._gcd_import(name[level:], package, level)\n",
      "  File \"<frozen importlib._bootstrap>\", line 1006, in _gcd_import\n",
      "  File \"<frozen importlib._bootstrap>\", line 983, in _find_and_load\n",
      "  File \"<frozen importlib._bootstrap>\", line 953, in _find_and_load_unlocked\n",
      "  File \"<frozen importlib._bootstrap>\", line 219, in _call_with_frames_removed\n",
      "  File \"<frozen importlib._bootstrap>\", line 1006, in _gcd_import\n",
      "  File \"<frozen importlib._bootstrap>\", line 983, in _find_and_load\n",
      "  File \"<frozen importlib._bootstrap>\", line 965, in _find_and_load_unlocked\n",
      "ModuleNotFoundError: No module named 'tensorflow_core'\n"
     ]
    },
    {
     "ename": "TypeError",
     "evalue": "can only concatenate str (not \"list\") to str",
     "output_type": "error",
     "traceback": [
      "\u001b[1;31m---------------------------------------------------------------------------\u001b[0m",
      "\u001b[1;31mModuleNotFoundError\u001b[0m                       Traceback (most recent call last)",
      "\u001b[1;32mc:\\users\\mady\\appdata\\local\\programs\\python\\python37\\lib\\site-packages\\keras\\__init__.py\u001b[0m in \u001b[0;36m<module>\u001b[1;34m\u001b[0m\n\u001b[0;32m      2\u001b[0m \u001b[1;32mtry\u001b[0m\u001b[1;33m:\u001b[0m\u001b[1;33m\u001b[0m\u001b[1;33m\u001b[0m\u001b[0m\n\u001b[1;32m----> 3\u001b[1;33m     \u001b[1;32mfrom\u001b[0m \u001b[0mtensorflow\u001b[0m\u001b[1;33m.\u001b[0m\u001b[0mkeras\u001b[0m\u001b[1;33m.\u001b[0m\u001b[0mlayers\u001b[0m\u001b[1;33m.\u001b[0m\u001b[0mexperimental\u001b[0m\u001b[1;33m.\u001b[0m\u001b[0mpreprocessing\u001b[0m \u001b[1;32mimport\u001b[0m \u001b[0mRandomRotation\u001b[0m\u001b[1;33m\u001b[0m\u001b[1;33m\u001b[0m\u001b[0m\n\u001b[0m\u001b[0;32m      4\u001b[0m \u001b[1;32mexcept\u001b[0m \u001b[0mImportError\u001b[0m\u001b[1;33m:\u001b[0m\u001b[1;33m\u001b[0m\u001b[1;33m\u001b[0m\u001b[0m\n",
      "\u001b[1;32mc:\\users\\mady\\appdata\\local\\programs\\python\\python37\\lib\\site-packages\\tensorflow\\__init__.py\u001b[0m in \u001b[0;36m__getattr__\u001b[1;34m(self, item)\u001b[0m\n\u001b[0;32m     49\u001b[0m \u001b[1;32mfrom\u001b[0m \u001b[1;33m.\u001b[0m\u001b[0m_api\u001b[0m\u001b[1;33m.\u001b[0m\u001b[0mv2\u001b[0m \u001b[1;32mimport\u001b[0m \u001b[0mconfig\u001b[0m\u001b[1;33m\u001b[0m\u001b[1;33m\u001b[0m\u001b[0m\n\u001b[1;32m---> 50\u001b[1;33m \u001b[1;32mfrom\u001b[0m \u001b[1;33m.\u001b[0m\u001b[0m_api\u001b[0m\u001b[1;33m.\u001b[0m\u001b[0mv2\u001b[0m \u001b[1;32mimport\u001b[0m \u001b[0mdata\u001b[0m\u001b[1;33m\u001b[0m\u001b[1;33m\u001b[0m\u001b[0m\n\u001b[0m\u001b[0;32m     51\u001b[0m \u001b[1;32mfrom\u001b[0m \u001b[1;33m.\u001b[0m\u001b[0m_api\u001b[0m\u001b[1;33m.\u001b[0m\u001b[0mv2\u001b[0m \u001b[1;32mimport\u001b[0m \u001b[0mdebugging\u001b[0m\u001b[1;33m\u001b[0m\u001b[1;33m\u001b[0m\u001b[0m\n",
      "\u001b[1;32mc:\\users\\mady\\appdata\\local\\programs\\python\\python37\\lib\\site-packages\\tensorflow\\__init__.py\u001b[0m in \u001b[0;36m_load\u001b[1;34m(self)\u001b[0m\n\u001b[0;32m     43\u001b[0m \u001b[1;33m\u001b[0m\u001b[0m\n\u001b[1;32m---> 44\u001b[1;33m \u001b[1;32mfrom\u001b[0m \u001b[1;33m.\u001b[0m\u001b[0m_api\u001b[0m\u001b[1;33m.\u001b[0m\u001b[0mv2\u001b[0m \u001b[1;32mimport\u001b[0m \u001b[0maudio\u001b[0m\u001b[1;33m\u001b[0m\u001b[1;33m\u001b[0m\u001b[0m\n\u001b[0m\u001b[0;32m     45\u001b[0m \u001b[1;32mfrom\u001b[0m \u001b[1;33m.\u001b[0m\u001b[0m_api\u001b[0m\u001b[1;33m.\u001b[0m\u001b[0mv2\u001b[0m \u001b[1;32mimport\u001b[0m \u001b[0mautodiff\u001b[0m\u001b[1;33m\u001b[0m\u001b[1;33m\u001b[0m\u001b[0m\n",
      "\u001b[1;32mc:\\users\\mady\\appdata\\local\\programs\\python\\python37\\lib\\importlib\\__init__.py\u001b[0m in \u001b[0;36mimport_module\u001b[1;34m(name, package)\u001b[0m\n\u001b[0;32m    126\u001b[0m             \u001b[0mlevel\u001b[0m \u001b[1;33m+=\u001b[0m \u001b[1;36m1\u001b[0m\u001b[1;33m\u001b[0m\u001b[1;33m\u001b[0m\u001b[0m\n\u001b[1;32m--> 127\u001b[1;33m     \u001b[1;32mreturn\u001b[0m \u001b[0m_bootstrap\u001b[0m\u001b[1;33m.\u001b[0m\u001b[0m_gcd_import\u001b[0m\u001b[1;33m(\u001b[0m\u001b[0mname\u001b[0m\u001b[1;33m[\u001b[0m\u001b[0mlevel\u001b[0m\u001b[1;33m:\u001b[0m\u001b[1;33m]\u001b[0m\u001b[1;33m,\u001b[0m \u001b[0mpackage\u001b[0m\u001b[1;33m,\u001b[0m \u001b[0mlevel\u001b[0m\u001b[1;33m)\u001b[0m\u001b[1;33m\u001b[0m\u001b[1;33m\u001b[0m\u001b[0m\n\u001b[0m\u001b[0;32m    128\u001b[0m \u001b[1;33m\u001b[0m\u001b[0m\n",
      "\u001b[1;31mModuleNotFoundError\u001b[0m: No module named 'tensorflow_core'",
      "\nDuring handling of the above exception, another exception occurred:\n",
      "\nDuring handling of the above exception, another exception occurred:\n",
      "\u001b[1;31mAttributeError\u001b[0m                            Traceback (most recent call last)",
      "\u001b[1;32mc:\\users\\mady\\appdata\\local\\programs\\python\\python37\\lib\\site-packages\\IPython\\core\\interactiveshell.py\u001b[0m in \u001b[0;36mshowtraceback\u001b[1;34m(self, exc_tuple, filename, tb_offset, exception_only, running_compiled_code)\u001b[0m\n\u001b[0;32m   2039\u001b[0m                         \u001b[1;31m# in the engines. This should return a list of strings.\u001b[0m\u001b[1;33m\u001b[0m\u001b[1;33m\u001b[0m\u001b[1;33m\u001b[0m\u001b[0m\n\u001b[1;32m-> 2040\u001b[1;33m                         \u001b[0mstb\u001b[0m \u001b[1;33m=\u001b[0m \u001b[0mvalue\u001b[0m\u001b[1;33m.\u001b[0m\u001b[0m_render_traceback_\u001b[0m\u001b[1;33m(\u001b[0m\u001b[1;33m)\u001b[0m\u001b[1;33m\u001b[0m\u001b[1;33m\u001b[0m\u001b[0m\n\u001b[0m\u001b[0;32m   2041\u001b[0m                     \u001b[1;32mexcept\u001b[0m \u001b[0mException\u001b[0m\u001b[1;33m:\u001b[0m\u001b[1;33m\u001b[0m\u001b[1;33m\u001b[0m\u001b[0m\n",
      "\u001b[1;31mAttributeError\u001b[0m: 'ImportError' object has no attribute '_render_traceback_'",
      "\nDuring handling of the above exception, another exception occurred:\n",
      "\u001b[1;31mTypeError\u001b[0m                                 Traceback (most recent call last)",
      "\u001b[1;32mc:\\users\\mady\\appdata\\local\\programs\\python\\python37\\lib\\site-packages\\IPython\\core\\interactiveshell.py\u001b[0m in \u001b[0;36mrun_code\u001b[1;34m(self, code_obj, result, async_)\u001b[0m\n\u001b[0;32m   3341\u001b[0m             \u001b[1;32mif\u001b[0m \u001b[0mresult\u001b[0m \u001b[1;32mis\u001b[0m \u001b[1;32mnot\u001b[0m \u001b[1;32mNone\u001b[0m\u001b[1;33m:\u001b[0m\u001b[1;33m\u001b[0m\u001b[1;33m\u001b[0m\u001b[0m\n\u001b[0;32m   3342\u001b[0m                 \u001b[0mresult\u001b[0m\u001b[1;33m.\u001b[0m\u001b[0merror_in_exec\u001b[0m \u001b[1;33m=\u001b[0m \u001b[0msys\u001b[0m\u001b[1;33m.\u001b[0m\u001b[0mexc_info\u001b[0m\u001b[1;33m(\u001b[0m\u001b[1;33m)\u001b[0m\u001b[1;33m[\u001b[0m\u001b[1;36m1\u001b[0m\u001b[1;33m]\u001b[0m\u001b[1;33m\u001b[0m\u001b[1;33m\u001b[0m\u001b[0m\n\u001b[1;32m-> 3343\u001b[1;33m             \u001b[0mself\u001b[0m\u001b[1;33m.\u001b[0m\u001b[0mshowtraceback\u001b[0m\u001b[1;33m(\u001b[0m\u001b[0mrunning_compiled_code\u001b[0m\u001b[1;33m=\u001b[0m\u001b[1;32mTrue\u001b[0m\u001b[1;33m)\u001b[0m\u001b[1;33m\u001b[0m\u001b[1;33m\u001b[0m\u001b[0m\n\u001b[0m\u001b[0;32m   3344\u001b[0m         \u001b[1;32melse\u001b[0m\u001b[1;33m:\u001b[0m\u001b[1;33m\u001b[0m\u001b[1;33m\u001b[0m\u001b[0m\n\u001b[0;32m   3345\u001b[0m             \u001b[0moutflag\u001b[0m \u001b[1;33m=\u001b[0m \u001b[1;32mFalse\u001b[0m\u001b[1;33m\u001b[0m\u001b[1;33m\u001b[0m\u001b[0m\n",
      "\u001b[1;32mc:\\users\\mady\\appdata\\local\\programs\\python\\python37\\lib\\site-packages\\IPython\\core\\interactiveshell.py\u001b[0m in \u001b[0;36mshowtraceback\u001b[1;34m(self, exc_tuple, filename, tb_offset, exception_only, running_compiled_code)\u001b[0m\n\u001b[0;32m   2041\u001b[0m                     \u001b[1;32mexcept\u001b[0m \u001b[0mException\u001b[0m\u001b[1;33m:\u001b[0m\u001b[1;33m\u001b[0m\u001b[1;33m\u001b[0m\u001b[0m\n\u001b[0;32m   2042\u001b[0m                         stb = self.InteractiveTB.structured_traceback(etype,\n\u001b[1;32m-> 2043\u001b[1;33m                                             value, tb, tb_offset=tb_offset)\n\u001b[0m\u001b[0;32m   2044\u001b[0m \u001b[1;33m\u001b[0m\u001b[0m\n\u001b[0;32m   2045\u001b[0m                     \u001b[0mself\u001b[0m\u001b[1;33m.\u001b[0m\u001b[0m_showtraceback\u001b[0m\u001b[1;33m(\u001b[0m\u001b[0metype\u001b[0m\u001b[1;33m,\u001b[0m \u001b[0mvalue\u001b[0m\u001b[1;33m,\u001b[0m \u001b[0mstb\u001b[0m\u001b[1;33m)\u001b[0m\u001b[1;33m\u001b[0m\u001b[1;33m\u001b[0m\u001b[0m\n",
      "\u001b[1;32mc:\\users\\mady\\appdata\\local\\programs\\python\\python37\\lib\\site-packages\\IPython\\core\\ultratb.py\u001b[0m in \u001b[0;36mstructured_traceback\u001b[1;34m(self, etype, value, tb, tb_offset, number_of_lines_of_context)\u001b[0m\n\u001b[0;32m   1383\u001b[0m         \u001b[0mself\u001b[0m\u001b[1;33m.\u001b[0m\u001b[0mtb\u001b[0m \u001b[1;33m=\u001b[0m \u001b[0mtb\u001b[0m\u001b[1;33m\u001b[0m\u001b[1;33m\u001b[0m\u001b[0m\n\u001b[0;32m   1384\u001b[0m         return FormattedTB.structured_traceback(\n\u001b[1;32m-> 1385\u001b[1;33m             self, etype, value, tb, tb_offset, number_of_lines_of_context)\n\u001b[0m\u001b[0;32m   1386\u001b[0m \u001b[1;33m\u001b[0m\u001b[0m\n\u001b[0;32m   1387\u001b[0m \u001b[1;33m\u001b[0m\u001b[0m\n",
      "\u001b[1;32mc:\\users\\mady\\appdata\\local\\programs\\python\\python37\\lib\\site-packages\\IPython\\core\\ultratb.py\u001b[0m in \u001b[0;36mstructured_traceback\u001b[1;34m(self, etype, value, tb, tb_offset, number_of_lines_of_context)\u001b[0m\n\u001b[0;32m   1286\u001b[0m             \u001b[1;31m# Verbose modes need a full traceback\u001b[0m\u001b[1;33m\u001b[0m\u001b[1;33m\u001b[0m\u001b[1;33m\u001b[0m\u001b[0m\n\u001b[0;32m   1287\u001b[0m             return VerboseTB.structured_traceback(\n\u001b[1;32m-> 1288\u001b[1;33m                 \u001b[0mself\u001b[0m\u001b[1;33m,\u001b[0m \u001b[0metype\u001b[0m\u001b[1;33m,\u001b[0m \u001b[0mvalue\u001b[0m\u001b[1;33m,\u001b[0m \u001b[0mtb\u001b[0m\u001b[1;33m,\u001b[0m \u001b[0mtb_offset\u001b[0m\u001b[1;33m,\u001b[0m \u001b[0mnumber_of_lines_of_context\u001b[0m\u001b[1;33m\u001b[0m\u001b[1;33m\u001b[0m\u001b[0m\n\u001b[0m\u001b[0;32m   1289\u001b[0m             )\n\u001b[0;32m   1290\u001b[0m         \u001b[1;32melif\u001b[0m \u001b[0mmode\u001b[0m \u001b[1;33m==\u001b[0m \u001b[1;34m'Minimal'\u001b[0m\u001b[1;33m:\u001b[0m\u001b[1;33m\u001b[0m\u001b[1;33m\u001b[0m\u001b[0m\n",
      "\u001b[1;32mc:\\users\\mady\\appdata\\local\\programs\\python\\python37\\lib\\site-packages\\IPython\\core\\ultratb.py\u001b[0m in \u001b[0;36mstructured_traceback\u001b[1;34m(self, etype, evalue, etb, tb_offset, number_of_lines_of_context)\u001b[0m\n\u001b[0;32m   1148\u001b[0m         \u001b[0mexception\u001b[0m \u001b[1;33m=\u001b[0m \u001b[0mself\u001b[0m\u001b[1;33m.\u001b[0m\u001b[0mget_parts_of_chained_exception\u001b[0m\u001b[1;33m(\u001b[0m\u001b[0mevalue\u001b[0m\u001b[1;33m)\u001b[0m\u001b[1;33m\u001b[0m\u001b[1;33m\u001b[0m\u001b[0m\n\u001b[0;32m   1149\u001b[0m         \u001b[1;32mif\u001b[0m \u001b[0mexception\u001b[0m\u001b[1;33m:\u001b[0m\u001b[1;33m\u001b[0m\u001b[1;33m\u001b[0m\u001b[0m\n\u001b[1;32m-> 1150\u001b[1;33m             \u001b[0mformatted_exceptions\u001b[0m \u001b[1;33m+=\u001b[0m \u001b[0mself\u001b[0m\u001b[1;33m.\u001b[0m\u001b[0mprepare_chained_exception_message\u001b[0m\u001b[1;33m(\u001b[0m\u001b[0mevalue\u001b[0m\u001b[1;33m.\u001b[0m\u001b[0m__cause__\u001b[0m\u001b[1;33m)\u001b[0m\u001b[1;33m\u001b[0m\u001b[1;33m\u001b[0m\u001b[0m\n\u001b[0m\u001b[0;32m   1151\u001b[0m             \u001b[0metype\u001b[0m\u001b[1;33m,\u001b[0m \u001b[0mevalue\u001b[0m\u001b[1;33m,\u001b[0m \u001b[0metb\u001b[0m \u001b[1;33m=\u001b[0m \u001b[0mexception\u001b[0m\u001b[1;33m\u001b[0m\u001b[1;33m\u001b[0m\u001b[0m\n\u001b[0;32m   1152\u001b[0m         \u001b[1;32melse\u001b[0m\u001b[1;33m:\u001b[0m\u001b[1;33m\u001b[0m\u001b[1;33m\u001b[0m\u001b[0m\n",
      "\u001b[1;31mTypeError\u001b[0m: can only concatenate str (not \"list\") to str"
     ]
    }
   ],
   "source": [
    "import keras\n",
    "\n",
    "import matplotlib as mp\n",
    "import numpy as np\n",
    "import pandas as pd\n"
   ]
  },
  {
   "cell_type": "code",
   "execution_count": null,
   "metadata": {},
   "outputs": [],
   "source": []
  }
 ],
 "metadata": {
  "kernelspec": {
   "display_name": "Python 3",
   "language": "python",
   "name": "python3"
  },
  "language_info": {
   "codemirror_mode": {
    "name": "ipython",
    "version": 3
   },
   "file_extension": ".py",
   "mimetype": "text/x-python",
   "name": "python",
   "nbconvert_exporter": "python",
   "pygments_lexer": "ipython3",
   "version": "3.7.3"
  }
 },
 "nbformat": 4,
 "nbformat_minor": 2
}
